## 自定义错误

### errors.New

自定义错误，返回一个 `error` 类型的值

```go
error.New("错误说明")
```

使用经验：

* 如果失败原因只有一个，则返回 `bool` 类型
* 如果失败原因不止一个，则返回 `error` 类型



## 抛出异常

使用内置函数 `panic`，接收任意值作为参数，引发异常

`panic` 可以在任何位置引发，但是 `recover` 只能在 `defer` 中调用

```go
panic("message") // 指定 panic 发生时显示的信息
```



## defer-panic-recover机制

### 机制说明

默认情况下，当发生错误`(panic)`后，程序就会崩溃

如果希望当发生 `panic` 后，可以捕捉到 `panic`，并进行处理，使程序不崩溃，则需要进行错误处理

`Go` 不支持传统的 `try-catch-finally`，而是使用 `defer-panic-recover`机制

### 流程

程序错误抛出一个 `panic`，然后在 `defer` 语句中通过 `recover` 函数捕获这个 `panic`，并处理，从而避免程序崩溃

### 示例

```go
package main

import "fmt"

func main() {
  test()
  fmt.Println("尽管发生了 panic，程序还是继续执行了") 
}

func test() {
  defer func() {
    err := recover() // recover内置函数，可以捕获异常
    if err != nil {
      fmt.Println("err=",err)
    }
  }()
   
  panic("引发异常")
}
```

### 注意

`recover()`必须搭配`defer`使用

`defer`一定要在可能引发`panic`的语句之前定义

`recover()` 必须在函数内部使用

```go
defer func() {
  recover() // 有效
}()

defer recover() // 无效
```

`panic` 比 `default` 优先级要高