## 捕获错误

### try..catch

```js
try {
  ...
} catch (e) {
  ...
}
```

### try...finally

```js
try {
  ...
} finally {
  ...
}
```

### try...catch...finally

```js
try {
  ...
} catch (e) {
  ...
} finally {
  ...
}
```



## 错误类型

JavaScript有一个标准的Error对象表示错误，Error是所有错误的父类型

还有从Error派生子错误类型

### 错误类型对象

| 属性    | 说明             |
| ------- | ---------------- |
| message | 错误的提示信息   |
| stack   | 错误的调用栈信息 |

### 常见错误类型

| 错误类型       | 说明     | 例子                         |
| -------------- | -------- | ---------------------------- |
| TypeError      | 类型错误 | 使用了对象中没有的属性或方法 |
| ReferenceError | 引用错误 | 使用了不存在的变量           |
| SyntaxError    | 语法错误 | 写错了JS语法                 |
| RangeError     | 越界错误 | 无限递归                     |



## 抛出错误

程序可以使用`throw`语句主动抛出一个错误，让执行流程直接跳转到catch块

```js
throw new Error("自定义提示信息")
```

实际上，JavaScript允许抛出任意对象，包括数字、字符串，但**最好还是抛出一个Error对象**

```js
var r, n, s;

try {
  s = prompt('请输入一个数字');
  n = parseInt(s);
  if (isNaN(n)) {
    throw new Error('输入错误');
  }
  // 计算平方:
  r = n * n;
  console.log(n + ' * ' + n + ' = ' + r);
} catch (e) {
  console.log('出错了：' + e);
}
```



## 错误传播

如果在一个函数内部发生了错误，它自身没有捕获，错误就会被抛到外层调用函数

如果外层函数也没有捕获，该错误会一直沿着函数调用链向上抛出，直到被JavaScript引擎捕获，代码终止执行

所以，我们不必在每一个函数内部捕获错误，只需要在合适的地方来个统一捕获，一网打尽



## finally解析

### finally原理

在return前，系统会自动创建一个临时变量，缓存返回值，finally是在缓存返回值和return之间调用的

```js
console.log("before return");
return data;

// 实际执行流程如下 //

console.log("before return");

const tempVal = data;
// 此处执行 finally 中的逻辑
return tempVal;
```

### finally中return

finally中是可以return的，而且这个地方一旦有了return，就会覆盖原本的return



## ES10增强

catch 的参数改为可选

在以前的JavaScript版本中，使用`try...catch`进行错误处理时，如果没有给catch传参数的话，代码就会报错

但有时候我们并不关心错误情况，如：

```js
const isValidJSON = json => {
  try {
    JSON.parse(json);
    return true;
  } catch (unusedError) {
    // Unused error parameter
    return false;
  }
};
```

在新规范中，我们可以省略catch绑定的参数和括号

```js
const isValidJSON = json => {
  try {
    JSON.parse(json);
    return true;
  } catch {
    return false;
  }
};
```

